Workbook

Sheet 01_Study_Coding
A1: ROS SLR 精简编码表 / Concise Study Coding
A2: 一篇文章一行。主缺陷代码只填一个；其他缺陷代码可用分号列出，但每个 Full/Partial 缺陷必须在 02_Defect_Evidence 中单独建立证据行。缺陷覆盖度与研究质量不得混用。
A3: Study ID | B3: Article Title / 文章标题 | C3: ROS Version | D3: Major Category | E3: 2-Major Category | F3: final-Major Category | G3: Primary Defect Code | H3: Primary Subcategory | I3: 2-Primary Subcategory | J3: final-Primary Subcategory | K3: Other Defect Code(s) | L3: ALL Defect Code | M3: Primary Impact | N3: Source Code Required | O3: Simulation Use | P3: QA1 ROS Relevance | Q3: QA2 Defect Clarity | R3: QA3 Study/Method Clarity | S3: QA4 Evaluation Strength | T3: QA5 Reproducibility | U3: QA Total (0-5) | V3: Adjudication / Notes | W3: Tools
A4: TBD | B4: A systematic review on cybersecurity of robotic systems: vulnerabilities trends, threats, attacks, challenges, and proposed framework | C4: ROS 1 | D4: VUL | E4: VUL | F4: VUL | G4: ROS1-UTA | H4: I; C; A | I4: I; C; A | J4: I; C; A | K4: ROS1-LE; ROS1-LNA; ROS1-LFQ | L4: ROS1-UTA; ROS1-LE; ROS1-LNA; ROS1-LFQ | M4: IMP-DT | N4: No | O4: No | P4: Partial | Q4: Partial | R4: Partial | S4: No | T4: No | U4: 1.5 | V4: Broad robotic-system cybersecurity review rather than a ROS-specific study. ROS 1 access control, encryption, authentication, and DoS weaknesses are explicitly synthesized from prior studies. ROS 2 is mentioned mainly as a limitation of an earlier secure-communication approach and through general DDS discussion; no ROS 2-specific defect is directly analyzed. The proposed framework is conceptual and not implemented or experimentally evaluated. | W4: No
A5: TBD | B5: Cyber security of robots: A comprehensive survey | C5: Both | D5: VUL | E5: VUL | F5: VUL | G5: ROS1-UTA | H5: I; C | I5: I; C | J5: I; C | K5: ROS1-LE; ROS1-LNA; ROS1-PNE | L5: ROS1-UTA; ROS1-LE; ROS1-LNA; ROS1-PNE | M5: IMP-DT | N5: No | O5: No | P5: Partial | Q5: Partial | R5: Partial | S5: Partial | T5: Partial | U5: 2.5 | V5: Broad survey of robot cybersecurity rather than a ROS-only study. ROS 1 and ROS 2 are both explicitly reviewed, but the codebook-matched defects concern mainly ROS 1 plaintext communication, unrestricted publishing/access, missing node authentication, and publicly exposed ROS instances. ROS 2 is principally discussed through DDS-Security, security APIs, mitigation mechanisms, and performance overhead; no sufficiently specific ROS 2 defect category is established. The paper reports seven databases, search period, inclusion/exclusion criteria, PRISMA counts, dual screening, and third-author adjudication, but omits exact database-specific queries, the complete extraction form, formal quality-assessment criteria, and a replication package. | W5: No
A6: TBD | B6: Robotics Cyber Security: Vulnerabilities, Attacks, Countermeasures, and Recommendations | C6: ROS 1 | D6: VUL | E6: VUL | F6: VUL | G6: ROS1-LE | H6: I | I6: C | J6: C; I | K6: ROS1-UTA | L6: ROS1-LE; ROS1-UTA | M6: IMP-DS | N6: No | O6: No | P6: Partial | Q6: Partial | R6: No | S6: No | T6: No | U6: 1 | V6: Broad narrative review of robotic cybersecurity rather than a ROS-specific or systematic review. ROS-specific discussion summarizes cryptographic protection for ROS communication and permission control over publishing, subscribing, and data consumption. No original ROS experiment, implementation, dataset, search protocol, quality assessment, or replication package is provided. | W6: No
A7: TBD | B7: An Empirical Study of Vulnerabilities in Robotics | C7: Both | D7: VUL | E7: VUL | F7: VUL | G7: — | H7: — | I7: — | J7: — | K7: — | L7: ROS1-LE; ROS1-PNE; ROS1-LNA; ROS1-LFQ | M7: — | N7: No | O7: No | P7: No | Q7: Full | R7: Full | S7: Full | T7: Full | U7: 4 | V7: Empirical analysis of 176 CVE-confirmed robotics vulnerabilities from RVD. ROS is mentioned only as an example within the “Operating System Software” component type, which accounts for 4.8% of software-related vulnerabilities. The paper does not identify which records are ROS-related, distinguish ROS 1 from ROS 2, or cross-tabulate ROS records with the nine vulnerability categories. Therefore, no codebook leaf can be assigned without unsupported inference. | W7: No
A8: TBD | B8: Security in Robot Operating Systems (ROS): Analytical Review Study | C8: Both | D8: VUL | E8: VUL | F8: VUL | G8: ROS1-UTA | H8: I; C; A | I8: I; C; A | J8: I; C; A | K8: ROS1-LE; ROS1-LNA; ROS1-PNE; ROS1-LFQ | L8: ROS1-UTA; ROS1-LE; ROS1-LNA; ROS1-PNE; ROS1-LFQ | M8: IMP-DT | N8: No | O8: No | P8: Full | Q8: Partial | R8: Partial | S8: Partial | T8: No | U8: 2.5 | V8: ROS security is the direct research object. The review compares ROS 1 and ROS 2 and synthesizes 32 studies, but provides no reproducible database-search procedure, selection criteria, extraction protocol, formal quality assessment, or replication package. ROS 1 access control, plaintext communication, anonymous node interaction, public exposure, and high-frequency publishing attacks are explicitly discussed. ROS 2 vulnerabilities are described only at a broad attack-category level and cannot be mapped reliably to the codebook’s mechanism-specific ROS 2 leaf codes. | W8: No
A9: TBD | B9: Who Controls Your Robot? An Evaluation of ROS Security Mechanisms | C9: Both | D9: VUL | E9: VUL | F9: VUL | G9: ROS2-ILE | H9: C; I | I9: C; I | J9: C; I | K9: ROS1-LE; ROS1-LNA; ROS1-UTA; ROS2-MPIB | L9: ROS2-ILE; ROS1-LE; ROS1-LNA; ROS1-UTA; ROS2-MPIB | M9: IMP-DS | N9: No | O9: No | P9: Full | Q9: Full | R9: Full | S9: Partial | T9: Partial | U9: 4 | V9: The paper directly evaluates network-security properties of ROS 1, ROS 2, and ten protection mechanisms. It defines MITM and compromised-node attackers and evaluates confidentiality, metadata confidentiality, integrity/authenticity, access control, compatibility, and key exchange. No original protection tool or complete runtime attack experiment is presented. ROS2-ILE is primary because the plaintext transmission of SROS 2/DDS-Security policies and ROS metadata is the most specific mechanism-level deficiency established by the study. | W9: No
A10: TBD | B10: Robot Operating System 2: The Need for a Holistic Security Approach to Robotic Architectures | C10: ROS 2 | D10: VUL | E10: VUL | F10: VUL | G10: ROS2-ILE | H10: C; I; A | I10: C; I; A | J10: C; I; A | K10: ROS2-ICAPP; ROS2-LRI; ROS2-CSCE | L10: ROS2-ILE; ROS2-ICAPP; ROS2-LRI; ROS2-CSCE | M10: IMP-DS | N10: No | O10: No | P10: Full | Q10: Full | R10: Full | S10: Partial | T10: Partial | U10: 4 | V10: The paper performs an architectural vulnerability analysis of ROS 2 and DDS-Security and experimentally evaluates security–performance trade-offs. The ROS translation layer is excluded from the benchmark; experiments measure RTI DDS messaging on one and two physical computers rather than a simulated robot. ROS2-ILE is primary because the paper directly demonstrates that security protection is independently configurable for discovery, liveliness, RTPS metadata, and payload, leaving selected information signed-only or completely unprotected. Credential/policy management, process isolation, and trusted security-component supply chains are identified as additional risks but are not experimentally exploited. | W10: No
A11: TBD | B11: Understanding Misconfigurations in ROS: An Empirical Study and Current Approaches | C11: Both | D11: REL | E11: REL | F11: REL | G11: ICF | H11: SEM; CODE | I11: SEM; CODE | J11: SEM; CODE | K11: BSE; SEF | L11: ICF; BSE; SEF | M11: IMP-FA | N11: No | O11: No | P11: Full | Q11: Full | R11: Full | S11: Partial | T11: Full | U11: 4.5 | V11: ROS misconfigurations are the direct research object. The study analyzes 228 real ROS Answers questions, derives 12 high-level and 50 fine-grained categories, and maps them to 18 existing techniques. ICF is primary because the dominant fault families concern names, message contracts, missing endpoints, remapping, namespaces, launch wiring, parameters, and component composition. BSE covers incorrect physical or behavioral meanings, while SEF covers queues, frequency, stale data, synchronization, and launch race conditions. Only 37 of 228 questions identify a ROS version, making version-specific classification infeasible; therefore, Unclear is more defensible than Both. The dataset is publicly released, but the tool-review evaluation is limited to selected venues and 2018–2022, and only 10 of 18 technique mappings received external author validation. | W11: No
A12: TBD | B12: The Role of Security in Human-Robot Shared Environments: A Case Study in ROS-based Surveillance Robots | C12: ROS 1 | D12: VUL | E12: VUL | F12: VUL | G12: ROS1-UTA | H12: I; C; A | I12: I; C; A | J12: I; C; A | K12: ROS1-LE; ROS1-LNA; ROS1-LFQ; ROS1-SPF | L12: ROS1-LE; ROS1-PNE; ROS1-LNA; ROS1-UTA; ROS1-SPF; ROS1-LFQ | M12: IMP-DT | N12: No | O12: No | P12: Full | Q12: Full | R12: Partial | S12: No | T12: No | U12: 2.5 | V12: The paper directly analyzes ROS 1 security weaknesses and uses the STOP multi-robot surveillance architecture as a case study. The primary weakness is unrestricted access to topics, nodes, and robot commands. Plaintext communication, missing node authentication, absent QoS/flow control, and the centralized ROS Master bottleneck are also explicitly discussed. The proposed hierarchical protections are largely design recommendations and ongoing implementation plans; the paper does not experimentally attack the STOP system or evaluate the proposed mechanisms quantitatively. | W12: No
A13: TBD | B13: A Study on ROS Vulnerabilities and Countermeasure | C13: ROS 1 | D13: VUL | E13: VUL | F13: VUL | G13: ROS1-LNA | H13: C | I13: I | J13: I; C | K13: ROS1-UTA; ROS1-LE; ROS1-LFQ; ROS1-SPF;ROS1-PNE | L13: ROS1-LE; ROS1-PNE; ROS1-LNA; ROS1-UTA; ROS1-SPF | M13: IMP-DT | N13: No | O13: Yes | P13: Full | Q13: Full | R13: Partial | S13: Partial | T13: Partial | U13: 3.5 | V13: The study experimentally analyzes ROS Indigo. An attacker joins the target ROS graph by configuring ROS_MASTER_URI, remotely controls TurtleSim, records and replays KOBUKI control messages, observes unencrypted communication, and replaces an existing service through duplicate-name registration. The attacks do not require application source code, although ROS Master source code is inspected to explain the service-hijacking mechanism. | W13: No
A14: TBD | B14: Smart Malware that Uses Leaked Control Data of Robotic Applications: The Case of Raven-II Surgical Robots | C14: ROS 1 | D14: VUL | E14: VUL | F14: VUL | G14: ROS1-UTA | H14: I; C | I14: I; C | J14: I; C | K14: ROS1-LNA; ROS1-LE | L14: ROS1-LE; ROS1-PNE; ROS1-LNA; ROS1-UTA; ROS1-SPF | M14: IMP-DT | N14: No | O14: Yes | P14: Full | Q14: Full | R14: Full | S14: Full | T14: Partial | U14: 4.5 | V14: The attack targets ROS 1 Kinetic and uses a malicious external ROS node to subscribe to sensitive state topics, infer critical surgical stages with DBSCAN, terminate or replace a legitimate publisher through a duplicate node name, and inject corrupted sensor/control data. The evaluation covers three simulated surgical scenarios, quantitative trigger accuracy, three fault payloads, and a safety module. Target application source code is not required, but the attacker needs network access, ROS APIs, relevant topic names, message structures, and some application knowledge. | W14: No
A15: TBD | B15: ROSploit: Cybersecurity Tool for ROS | C15: ROS 1 | D15: VUL | E15: VUL | F15: VUL | G15: ROS1-UTA | H15: I; C | I15: I; C | J15: I; C | K15: ROS1-LNA; ROS1-LE | L15: ROS1-LE; ROS1-PNE; ROS1-LNA; ROS1-UTA; ROS1-SPF; ROS1-LFQ | M15: IMP-DT | N15: No | O15: No | P15: Full | Q15: Full | R15: Partial | S15: Partial | T15: No | U15: 3 | V15: The paper presents a modular offensive tool with reconnaissance and exploitation components. ROSploit scans the ROS Master and arbitrary ports, enumerates nodes, topics, and services, and supports topic-level MITM attacks that can modify communications. The target application source code is not required. Evaluation is limited to a qualitative comparison between ROSploit scan results and the native ROS graph; no quantitative exploit evaluation, test repetitions, complete experimental configuration, or public replication package is reported. | W15: No
... A94: TBD | B94: ROSDiscover: Statically Detecting Run-Time Architecture Misconfigurations in Robotics Systems | C94: ROS 1 | D94: REL | E94: REL | F94: REL | G94: ICF | H94: SEM | I94: SEM | J94: SEM | K94: — | L94: ICF | M94: IMP-FA | N94: Yes | O94: Yes | P94: Full | Q94: Full | R94: Full | S94: Full | T94: Full | U94: 5 | V94: ROSDiscover reconstructs component ports, parameters and connectors from C++ source code, CMake files and ROS launch files, then checks the recovered architecture using first-order logic rules. It detects topic-name and message-type mismatches, incorrect topic remapping, dangling publishers/subscribers and architecture-related parameter misconfigurations. Evaluation uses five real ROS systems and a dataset of 29 historical bugs; 19 bugs fall within the implemented scope and 8 are detected directly. The implementation, dataset, Docker images, scripts and results are publicly available. | W94: Yes

Sheet 02_Defect_Evidence
A1: 缺陷证据表 / Defect-Level Evidence
A3: Study ID | B3: Article Title | C3: Defect Code | D3: Major Category | E3: Subcategory | F3: Coverage | G3: Evidence Statement / 证据 | H3: Evidence Location | I3: Impact Category | J3: Evidence Provenance | K3: Notes | L3: 列1 | M3: 列2 | N3: 列3 | O3: 列4 | P3: 列5 | Q3: 列6
A4: TBD | B4: A systematic review on cybersecurity of robotic systems: vulnerabilities trends, threats, attacks, challenges, and proposed framework | C4: ROS1-UTA | D4: VUL | E4: I | F4: Partial | G4: The review states that ROS lacks a mechanism for regulating information distribution between nodes, allowing a network-visible node to transmit information on a topic. It also summarizes false-data injection, unauthorized node publishing, and unauthorized publisher/subscriber attacks. | H4: Sec. 3.1.1, p. 13; Sec. 3.2.1, p. 18; Table 11, pp. 29–30 | I4: IMP-DT | J4: EP-HIST | K4: Primary code. Explicitly discussed and supported by external studies, but not independently evaluated by this paper.
A5: TBD | B5: A systematic review on cybersecurity of robotic systems: vulnerabilities trends, threats, attacks, challenges, and proposed framework | C5: ROS1-LE | D5: VUL | E5: C | F5: Partial | G5: The paper explicitly states that ROS messages can be transmitted without encryption, enabling eavesdropping, and discusses TLS/DTLS and encryption-based secure channels as countermeasures. | H5: Sec. 3.1.1, p. 13; Sec. 3.2.1, p. 18; Table 11, p. 29 | I5: IMP-DS | J5: EP-HIST | K5: Plaintext communication is explicitly described, but the authors perform no packet capture or independent ROS experiment.
A6: TBD | B6: A systematic review on cybersecurity of robotic systems: vulnerabilities trends, threats, attacks, challenges, and proposed framework | C6: ROS1-LNA | D6: VUL | E6: I | F6: Partial | G6: The review identifies poor authentication and unauthorized ROS nodes as common weaknesses and summarizes an authentication-server architecture intended to control which nodes may publish or subscribe. | H6: Sec. 3.2.1, p. 18; Table 11, p. 29 | I6: IMP-DT | J6: EP-HIST | K6: Authentication weakness is explicit, but evidence is a secondary synthesis of earlier work.
A7: TBD | B7: A systematic review on cybersecurity of robotic systems: vulnerabilities trends, threats, attacks, challenges, and proposed framework | C7: ROS1-LFQ | D7: VUL | E7: A | F7: Partial | G7: The paper reviews ROS middleware DoS attacks caused by large numbers of unauthorized publishers or subscribers. It reports increased processing, storage consumption, network unresponsiveness, message delay, and packet loss. | H7: Sec. 3.1.1, p. 13; Sec. 4 discussion, p. 27; Table 11, pp. 29–30 | I7: IMP-RE | J7: EP-HIST | K7: The DoS mechanism is consistent with malicious high-rate publishing and connection occupation, but the experiments belong to cited studies rather than this review.
A8: TBD | B8: Cyber security of robots: A comprehensive survey | C8: ROS1-UTA | D8: VUL | E8: I | F8: Partial | G8: The survey reports that an attacker inside a ROS network can send shutdown commands, publish adulterated messages, manipulate velocity commands, inject false or malicious data, and access ROS services without sufficient authorization. | H8: Sec. 3.3, p. 5; Sec. 5.3, p. 9; Sec. 6.5, p. 12; Sec. 8.2, p. 13 | I8: IMP-DT | J8: EP-HIST | K8: Primary code. The weakness and attack consequences are explicitly synthesized from previous studies, but this paper does not independently execute or evaluate the attacks.
A9: TBD | B9: Cyber security of robots: A comprehensive survey | C9: ROS1-LE | D9: VUL | E9: C | F9: Partial | G9: The paper identifies unsecured ROS-to-ROS and node-to-node ports that communicate in plaintext. It also summarizes plain-text communications, unencrypted storage, and encryption-based countermeasures for protecting ROS node communication. | H9: Sec. 3.3, p. 5; Sec. 4.3, pp. 7–8; Sec. 6.1, p. 10 | I9: IMP-DS | J9: EP-HIST | K9: Directly matches absent channel protection in ROS 1, but the evidence is secondary and no packet-level experiment is performed by the survey authors.
A10: TBD | B10: Cyber security of robots: A comprehensive survey | C10: ROS1-LNA | D10: VUL | E10: I | F10: Partial | G10: The survey explicitly describes weak ROS authentication, unauthorized or rogue nodes, and the ability of malicious nodes to execute commands or alter robot behavior. It reviews authentication nodes, authorization servers, web tokens, and trusted-node mechanisms as countermeasures. | H10: Sec. 4.3, pp. 7–8; Sec. 5.3, p. 9; Sec. 6.5, p. 12; Sec. 8.2, p. 13 | I10: IMP-DT | J10: EP-HIST | K10: The paper distinguishes unauthorized nodes and weak authentication from authorization of topic/service operations, supporting a separate LNA code.
A11: TBD | B11: Cyber security of robots: A comprehensive survey | C11: ROS1-PNE | D11: VUL | E11: C | F11: Partial | G11: The paper states that publicly exposed ROS instances allow malicious users to access sensors and read images or other sensor information. It also cites an Internet-wide scan reporting more than 100 ROS Master instances accessible from the public Internet. | H11: Sec. 4.2, p. 7; Sec. 5.3, p. 9 | I11: IMP-DS | J11: EP-HIST | K11: Explicit evidence of external network reachability and public ROS Master exposure. The Internet scan was conducted by a cited study rather than by the survey authors.
A12: TBD | B12: Robotics Cyber Security: Vulnerabilities, Attacks, Countermeasures, and Recommendations | C12: ROS1-LE | D12: VUL | E12: C | F12: Partial | G12: The paper reviews cryptographic protection for ROS communication channels and the integration of TLS and DTLS into the ROS core. This explicitly indicates that baseline ROS communication requires additional channel protection to preserve confidentiality. | H12: Sec. V-E, “Cryptographic Solutions & Protocols,” p. 21 | I12: IMP-DS | J12: EP-HIST | K12: Primary code. The evidence is a secondary synthesis of cited ROS security studies; the authors do not independently intercept ROS traffic or evaluate plaintext communication.
A13: TBD | B13: Robotics Cyber Security: Vulnerabilities, Attacks, Countermeasures, and Recommendations | C13: ROS1-UTA | D13: VUL | E13: I | F13: Partial | G13: The reviewed ROS security solution introduces fine-grained control over permission to publish, subscribe, or consume data. The paper therefore explicitly recognizes the need to restrict ROS communication operations through authorization controls. | H13: Sec. V-E, “Cryptographic Solutions & Protocols,” p. 21 | I13: IMP-DT | J13: EP-HIST | K13: This is discussed through a cited countermeasure rather than an independently demonstrated unauthorized publication, subscription, or service call.
A14: TBD | B14: Security in Robot Operating Systems (ROS): Analytical Review Study | C14: ROS1-UTA | D14: VUL | E14: I | F14: Partial | G14: The paper states that ROS publishers cannot control who consumes their information and that unauthorized nodes can record data or publish injected messages. It further identifies access control over topic publishing and subscription as a necessary protection mechanism. | H14: Introduction, p. 2; Table 4, pp. 8–9; Table 6, p. 11 | I14: IMP-DT | J14: EP-HIST | K14: Primary code. The issue is explicitly analyzed as a ROS security weakness, but evidence is synthesized from prior studies rather than independently demonstrated.
A15: TBD | B15: Security in Robot Operating Systems (ROS): Analytical Review Study | C15: ROS1-LE | D15: VUL | E15: C | F15: Partial | G15: ROS 1 network traffic is described as being transmitted in a basic, unprotected form, making it susceptible to packet eavesdropping, man-in-the-middle attacks, and network hijacking. The review states that encryption is required to protect confidential ROS information. | H15: Sec. IV, p. 7; Table 4, p. 8 | I15: IMP-DS | J15: EP-HIST | K15: Directly supports absent channel protection in ROS 1, but the authors conduct no packet capture or communication experiment.
... A196: TBD | B196: ROSDiscover: Statically Detecting Run-Time Architecture Misconfigurations in Robotics Systems | C196: ICF | D196: REL | E196: SEM | F196: Full | G196: ROSDiscover detects inconsistent composition and configuration of ROS components, including mismatched topic names, incompatible publisher/subscriber message types, incorrect topic remappings, dangling communication endpoints, missing parameters and parameters configured with incompatible names, paths or types. The Autoware example in Figure 1 shows that renaming a publisher topic from line_class to line without updating subscribers disconnects the nodes and silently prevents message delivery. The evaluation corpus contains real configuration bugs from AutoRally, Autoware, MAVROS, Husky and TurtleBot. | H196: Sec. I–II, pp. 112–114; Fig. 1, p. 114; Sec. III, pp. 115–117; Sec. IV-C, pp. 119–120; Tables I and VI | I196: IMP-FA | J196: EP-OBS | K196: Primary and only defect code. The faults are reproduced from real historical commits and checked against corrected versions. They concern ROS component interfaces, connectors, parameters and launch-time composition.

Sheet 03_Codebook
A1: ROS Defect Codebook
A2: The fixed hierarchy is Major Category → Subcategory → Defect Code. Reliability faults are coded by the primary root-cause locus, not by symptoms or impacts.
A4: Subcategories
A5: Code | B5: Applies To | C5: Name | D5: Operational Meaning | E5: Key Boundary
A6: C | B6: VUL | C6: Confidentiality | D6: Unauthorized observation of data, metadata, or communication structure. | E6: Use only for security weaknesses; benign data-format errors are not C.
A7: I | B7: VUL | C7: Integrity | D7: Unauthorized forgery, modification, injection, replay, or reconfiguration. | E7: Benign configuration errors must be coded as REL.
A8: A | B8: VUL | C8: Availability | D8: Service disruption, overload, or resource exhaustion caused by an attack or missing security control. | E8: Benign scheduling or execution errors should be coded as SEF.
A9: CODE | B9: REL | C9: Code-Level | D9: The root cause lies in build/dependency artifacts, implementation code, or ROS runtime execution mechanisms. | E9: Includes BDF, SEF, and GPE.
A10: SEM | B10: REL | C10: Semantic-Logic | D10: The root cause lies in relationships among ROS entities or in robot, physical, or behavioral semantics. | E10: Includes ICF and BSE.
A11: Defect Codes
A12: Code | B12: Major Category | C12: ROS Version | D12: Subcategory | E12: English Name | F12: Concise Label | G12: Operational Definition | H12: Include When | I12: Exclude When | J12: Typical Evidence
A13: ROS1-LE | B13: VUL | C13: ROS 1 | D13: C | E13: Lack of Encryption | F13: No Encryption | G13: ROS 1 topic, service, TCPROS, UDPROS, or XMLRPC traffic is transmitted in plaintext. | H13: The study directly analyzes plaintext communication, eavesdropping, or absent channel protection. | I13: Do not use for benign data-format, message-semantic, or parsing errors. | J13: Packet captures, plaintext topics, or intercepted sensor/control data.
A14: ROS1-PNE | B14: VUL | C14: ROS 1 | D14: C | E14: Public Network Exposure | F14: Public Exposure | G14: The ROS Master or node endpoints can be discovered or reached from outside the intended local network because access restrictions are absent or inadequate. | H14: The study provides evidence of exposed ports, Internet scanning, remote reachability, or open interfaces. | I14: Do not code when communication is confined to the intended local network and external exposure is not demonstrated. | J14: Open ROS ports, an exposed Master, or Internet-scan results.
A15: ROS1-LNA | B15: VUL | C15: ROS 1 | D15: I | E15: Lack of Node Authentication | F15: No Node Authentication | G15: Nodes are not authenticated when registering, publishing, subscribing, or providing services. | H15: The study demonstrates malicious node registration, service hijacking, node impersonation, or authentication bypass. | I15: Benign node-name, topic-name, or namespace mistakes belong to ICF. | J15: Service re-registration, node impersonation, or absence of certificate/challenge validation.
A16: ROS1-UTA | B16: VUL | C16: ROS 1 | D16: I | E16: Unrestricted Topic and Service Access | F16: Unrestricted Access | G16: Network-visible nodes can publish, subscribe, or invoke sensitive topics and services without authorization. | H16: The study demonstrates unauthorized publishing, subscribing, service invocation, message injection, or replay. | I16: Accidental topic wiring or type mismatches belong to ICF. | J16: Forged /cmd_vel messages, unauthorized service calls, or topic injection.
A17: ROS1-IPS | B17: VUL | C17: ROS 1 | D17: I | E17: Insecure Parameter Server | F17: Insecure Parameters | G17: The ROS 1 Parameter Server lacks adequate authentication or authorization, enabling unauthorized parameter reads or writes. | H17: An attacker directly reads, overwrites, or manipulates runtime parameters. | I17: Benign incorrect parameter values or parameter paths should be considered BSE or ICF, respectively. | J17: Unauthorized modification of thresholds, control gains, or configuration parameters.
A18: ROS1-SPF | B18: VUL | C18: ROS 1 | D18: A | E18: Master as a Single Point of Failure | F18: Master Single Point | G18: Failure or attack of the centralized ROS Master can disrupt name resolution, discovery, or system coordination. | H18: The study explicitly exploits or evaluates the centralized weakness of the ROS Master. | I18: Ordinary node startup failures, build failures, or a crash of one non-Master node do not belong here. | J18: Master crashes, SlowROS, or graph-resolution failure.
A19: ROS1-LFQ | B19: VUL | C19: ROS 1 | D19: A | E19: Lack of Flow Control and QoS | F19: No Flow/QoS Control | G19: ROS 1 lacks adequate rate limiting, priority, queue control, or QoS guarantees, and this deficiency is exploited by malicious traffic. | H19: An attacker causes overload or denial of service through high-rate publishing, connection occupation, or selective message suppression. | I19: Benign callback blocking, queue configuration, or executor problems belong to SEF. | J19: Topic flooding, subscriber overload, or message loss.
A20: ROS2-ILE | B20: VUL | C20: ROS 2 | D20: C | E20: Incomplete or Leaky Encryption | F20: Leaky Encryption | G20: DDS-Security or SROS2 does not fully encrypt traffic, or handshake, policy, or metadata remains exposed. | H20: The study directly analyzes partial encryption, signing without encryption, or metadata leakage. | I20: Ordinary message-format or semantic errors do not belong here. | J20: Observed handshake metadata, permission information, or unencrypted payloads.
A21: ROS2-LMLAC | B21: VUL | C21: ROS 2 | D21: C | E21: Lack of Message-Level Access Control | F21: No Message-Level Control | G21: Node- or topic-level permissions lack the granularity needed to protect individual messages or fields. | H21: An over-privileged node reads protected messages and relays them to an unsecured channel. | I21: Benign publisher/subscriber mismatches belong to ICF. | J21: Confused-deputy behavior or protected data relayed to an insecure topic.
A22: ROS2-CSCE | B22: VUL | C22: ROS 2 | D22: C | E22: Cryptographic Supply Chain Exposure | F22: Crypto Supply Chain | G22: External cryptographic libraries or components on which ROS 2 security depends can be replaced, tampered with, or compromised through the supply chain, undermining security guarantees. | H22: The study explicitly analyzes compromise of a cryptographic dependency and its effect on session keys or encryption. | I22: Ordinary dependency declarations, builds, or installation errors belong to BDF. | J22: OpenSSL or cryptographic-library replacement and session-key leakage.
A23: ROS2-ICAPP | B23: VUL | C23: ROS 2 | D23: I | E23: Inadequate Credential and Policy Protection | F23: Weak Credential Protection | G23: Certificates, keys, governance files, or permission files lack adequate local integrity protection. | H23: An attacker modifies, replaces, or downgrades credentials or policies to impersonate an identity or escalate privileges. | I23: Non-malicious policy syntax or configuration errors should be coded as REL only when the study analyzes them as reliability faults. | J23: Permission-file modification, certificate replacement, or privilege escalation.
... A31: BSE | B31: REL | C31: ROS 1 / ROS 2 | D31: SEM | E31: Behavioral and Semantic Errors | F31: Behavioral/Semantic | G31: The root cause lies in robot models, transform values or conventions, physical units, parameter meaning, task logic, domain constraints, or explicit behavioral properties. | H31: Unit confusion, incorrect TF values or conventions, invalid URDF/SDF mass, inertia, or joint limits, invalid control parameters, or violated properties/invariants. | I31: Observed incorrect behavior alone is insufficient; incorrect interface relationships belong to ICF; generic code logic errors belong to GPE. | J31: Comparison of expected semantics or constraints with actual values, models, or execution traces.
A33: Impact Categories
A34: Code | B34: English Name | C34: Concise Label | D34: Operational Definition
A35: IMP-DS | B35: Data Snooping | C35: Unauthorized Data Access | D35: Unauthorized observation of ROS data, metadata, maps, sensor streams, or control messages.
A36: IMP-DT | B36: Data Tampering | C36: Unauthorized Modification | D36: Data, messages, services, or configurations are modified, forged, injected, replayed, or reconfigured without authorization.
A37: IMP-RE | B37: Resource Exhaustion | C37: Denial of Service | D37: Flooding, CPU or memory exhaustion, Master/node overload, or denial of service.
A38: IMP-FA | B38: Functional Anomaly | C38: Incorrect Behavior | D38: The system continues to run but behaves incorrectly, inconsistently, unsafely, or with degraded functionality.
A39: IMP-OA | B39: Operational Anomaly | C39: Hard Failure | D39: Build, deployment, or startup failure; node or system crash, freeze, deadlock, or inability to operate.

Sheet 04_Coding_Rules
A1: ROS SLR Operational Coding Rules
A2: This manual is aligned with the current manuscript taxonomy: vulnerabilities are classified by ROS version and CIA; reliability faults are classified as CODE or SEM, with BDF, SEF, GPE, ICF, and BSE as the only reliability leaf codes.
A4: A. Core Coding Sequence
A5: Step | B5: Decision | C5: Rule | D5: Allowed Result | E5: Do Not | F5: Example
A6: 1 | B6: Determine the ROS version | C6: Use only the actual study object, implementation, or evaluation. Background, related work, and future work do not count. | D6: ROS 1 / ROS 2 / Both / Unclear | E6: Code Both merely because ROS 2 is mentioned. | F6: Experiments on ROS Indigo → ROS 1.
A7: 2 | B7: Determine the major category | C7: Malicious exploitation, unauthorized behavior, or a missing security policy → VUL; non-malicious internal fault → REL. | D7: VUL / REL / BOTH | E7: Automatically code BOTH because an attack causes a crash. | F7: Attack-induced node crash → VUL + IMP-OA.
A8: 3 | B8: Determine the subcategory | C8: For VUL, select C, I, or A. For REL, select CODE or SEM. | D8: C / I / A / CODE / SEM | E8: Infer the subcategory from the final impact. | F8: Incorrect topic name → SEM.
A9: 4 | B9: Select the leaf code | C9: Code the earliest, most specific, evidence-supported primary root-cause locus. | D9: One of the 19 defect codes | E9: Assign multiple reliability codes to the same fault instance based on its symptoms. | F9: Queue overflow → SEF, not ICF.
A10: 5 | B10: Handle multiple defects | C10: A study may receive multiple codes, but each code must correspond to a distinct fault instance or fault family and have separate evidence. | D10: Primary code + other code(s) | E10: Add unevaluated codes merely because a tool claims broad support. | F10: Topic mismatch = ICF; unit mismatch = BSE.
A11: 6 | B11: Record the impact | C11: The defect code describes the root cause; Impact describes the system consequence. Keep them separate. | D11: IMP-DS / IMP-DT / IMP-RE / IMP-FA / IMP-OA | E11: Use crash, delay, or wrong motion as a defect code. | F11: Null dereference = GPE; crash = IMP-OA.
A12: 7 | B12: Record evidence | C12: State both the evidence and its location. Full or Partial cannot be based only on a broad summary statement. | D12: Section / Page / Table / Figure / Repository | E12: Write only “the paper discusses this issue.” | F12: Sec. 4.2, Fig. 3, p. 7.
A14: B. Defect Coverage: Full / Partial / No
A15: Judgment | B15: Operational Meaning | C15: Required Evidence | D15: Not Sufficient | E15: Long-Form Use | F15: Score
A16: Full | B16: The defect category is a direct object of the study, method, or evaluation. | C16: An explicit fault instance, data label, experimental case, or primary empirical analysis. | D16: Mention only in background; an unsupported claim that the tool can address it. | E16: Create an evidence row in 02_Defect_Evidence. | F16: 1
A17: Partial | B17: The category is explicitly addressed but not directly evaluated, or appears only as a secondary mechanism or capability statement. | C17: Explicit textual discussion, secondary analysis, or a clearly stated but unevaluated capability boundary. | D17: Inference only from a downstream symptom, without root-cause evidence. | E17: An evidence row may be created, but the limitation must be stated. | F17: 0.5
A18: No | B18: There is insufficient evidence for the category. | C18: No direct instance, analysis, or explicit capability statement. | D18: Do not infer from topical similarity. | E18: Normally omitted from the long-form sheet; omission means No. | F18: 0
A20: C. Study Quality Assessment (Full = 1, Partial = 0.5, No = 0)
A21: Criterion | B21: Full | C21: Partial | D21: No | E21: Evidence to Record | F21: Note
A22: QA1 ROS Relevance | B22: ROS is the research object, and the defect or method directly targets ROS mechanisms or a ROS-based system. | C22: ROS is a necessary experimental platform, but the research object is not fully ROS-specific. | D22: ROS is only an implementation tool or incidental background. | E22: Research question, target system, and experimental platform. | F22: Do not assign Full merely because ROS is used.
A23: QA2 Defect Clarity | B23: The defect, root cause, trigger conditions, and boundary are clearly defined. | C23: Only a broad category or symptom is given, while the root cause is partially clear. | D23: It is not possible to determine which defect the study actually examines. | E23: Definition, fault instance, and attack/fault model. | F23: Judge by root cause, not by impact.
A24: QA3 Study/Method Clarity | B24: Inputs, process, outputs, and key steps are sufficiently clear to understand or reproduce the work. | C24: The overall process is clear, but key implementation details or parameters are missing. | D24: The method or empirical procedure is inadequately described. | E24: Algorithm, workflow diagram, configuration, and parameters. | F24: For empirical studies, assess the reported research procedure.
A25: QA4 Evaluation Strength | B25: System or data, baselines, metrics, settings, and results are clearly reported and cover the main claims. | C25: The evaluation has limited cases, incomplete baselines or metrics, or small scale. | D25: There is no substantive evaluation, or only a conceptual example is provided. | E25: Dataset, subjects, metrics, repetitions, and results. | F25: Do not judge quality by whether the result is statistically significant.
A26: QA5 Reproducibility | B26: Code, data, and configuration are public, or the reported details are sufficient for independent reproduction. | C26: Only part of the artifacts is public, or key details remain missing. | D26: No artifacts are available and the description is insufficient for reproduction. | E26: Repository, data, versions, parameters, and reproduction steps. | F26: Assess availability as of the paper's publication.
A28: D. Tool and Evaluation-Environment Flags
A29: Field | B29: Value | C29: Definition | D29: Boundary | E29: Example | F29: Use in 01_Study_Coding
A30: Source Code Required | B30: Yes | C30: The method requires the target node/package source code as input, or requires source-level analysis, transformation, or instrumentation. | D30: Requiring only package.xml, launch files, or configuration files does not automatically count as source-code dependence. | E30: Static source-code analyzer. | F30: Yes
A31: Source Code Required | B31: No | C31: The method can operate using binaries, network traffic, rosbag data, runtime messages/graphs, logs, or deployment configuration only. | D31: Use Mixed when both source-dependent and source-independent modes are present. | E31: Network IDS or runtime monitor. | F31: No
A32: Source Code Required | B32: Mixed | C32: The same method includes both source-dependent and source-independent paths, or evaluates the two modes separately. | D32: Do not code Mixed merely because the paper publishes its own source code. | E32: Combined static and dynamic framework. | F32: Mixed
A33: Source Code Required | B33: N/A | C33: The study provides no executable detection/mitigation tool, or the field is not applicable. | D33: Do not force an empirical study or survey into Yes or No. | E33: Pure empirical defect study. | F33: N/A
A34: Simulation Use | B34: Yes | C34: Runtime evaluation is performed only in a simulator, emulated system, or synthetic ROS environment. | D34: Use N/A for static analysis or formal verification with no runtime environment. | E34: Gazebo-only or Stage-only evaluation. | F34: Yes
A35: Simulation Use | B35: No | C35: Runtime evaluation does not use a simulator or emulated system; this may include a physical robot, real hardware, deployed system, or standalone ROS testbed. | D35: The criterion is whether simulation/emulation is used, not whether a physical robot is necessarily present. | E35: Physical TurtleBot or laboratory ROS network testbed. | F35: No
A36: Simulation Use | B36: Hybrid | C36: The evaluation includes both simulation and a physical robot or real deployment. | D36: Using multiple simulators is still Yes, not Hybrid. | E36: Gazebo plus a physical robot. | F36: Hybrid
A37: Simulation Use | B37: N/A | C37: There is no runtime experiment, such as in static analysis, formal proof, secondary research, or pure data analysis. | D37: Use Unclear when execution experiments exist but the paper does not state whether simulation was used. | E37: Model checking without system execution. | F37: N/A
A39: E. Common Boundary Cases
A40: Scenario | B40: Correct Code | C40: Do Not Also Code | D40: Impact | E40: Reason | F40: Evidence
A41: A node subscribes to the wrong topic name, so the robot does not move. | B41: ICF | C41: BSE | D41: IMP-FA | E41: The primary root cause is interface wiring; immobility is only the consequence. | F41: Evidence of the incorrect topic/remap and the missing message flow.
A42: The message arrives correctly, but degrees are interpreted as radians. | B42: BSE | C42: ICF | D42: IMP-FA | E42: The interface works; the defect lies in physical semantics. | F42: Expected unit, actual unit, and the resulting incorrect value or behavior.
A43: A long-running callback causes queue overflow and message loss. | B43: SEF | C43: ICF | D43: IMP-FA or IMP-OA | E43: The root cause is the execution/queue mechanism, not the interface contract. | F43: Callback duration, queue state, and timing traces.
A44: ROS 2 endpoints cannot communicate because their QoS settings are incompatible. | B44: ICF | C44: SEF | D44: IMP-FA | E44: Compatibility or configuration prevents interaction. | F44: QoS profiles of both endpoints and incompatibility logs.
A45: A missing runtime dependency in package.xml causes deployment failure. | B45: BDF | C45: GPE | D45: IMP-OA | E45: The root cause lies in dependency metadata. | F45: Manifest contents and build/deployment error.
...

Sheet 05_Coding_Audit
A1: Inter-rater Coding Audit / 双人编码分析记录
A2: The final code was produced only after comparing both independent codes and re-checking the full-text evidence and coding rules.
A4: Full coding audit: 91 studies | D4: κ sample: source rows 60–86 (N=27) | G4: Sample major disagreements: 0 | I4: Sample primary disagreements: 3
A6: Primary Subcategory is a multi-label field. Each label set is canonicalized in the order C; I; A; CODE; SEM, and exact-set agreement is used. Cohen's kappa is estimated only on the randomly selected validation sample (source rows 60–86, N=27).
A8: No. | B8: Source Row | C8: Article Title / 文章标题 | D8: Major R1 | E8: Major R2 | F8: Major Agreement | G8: Final Major | H8: Primary R1 (normalized) | I8: Primary R2 (normalized) | J8: Primary Agreement | K8: Final Primary (normalized)
A9: 1 | B9: 4 | C9: A systematic review on cybersecurity of robotic systems: vulnerabilities trends, threats, attacks, challenges, and proposed framework | D9: VUL | E9: VUL | F9: Agree | G9: VUL | H9: C; I; A | I9: C; I; A | J9: Agree | K9: C; I; A
A10: 2 | B10: 5 | C10: Cyber security of robots: A comprehensive survey | D10: VUL | E10: VUL | F10: Agree | G10: VUL | H10: C; I | I10: C; I | J10: Agree | K10: C; I
A11: 3 | B11: 6 | C11: Robotics Cyber Security: Vulnerabilities, Attacks, Countermeasures, and Recommendations | D11: VUL | E11: VUL | F11: Agree | G11: VUL | H11: I | I11: C | J11: Disagree | K11: C; I
A12: 4 | B12: 7 | C12: An Empirical Study of Vulnerabilities in Robotics | D12: VUL | E12: VUL | F12: Agree | G12: VUL | H12: — | I12: — | J12: Agree | K12: —
A13: 5 | B13: 8 | C13: Security in Robot Operating Systems (ROS): Analytical Review Study | D13: VUL | E13: VUL | F13: Agree | G13: VUL | H13: C; I; A | I13: C; I; A | J13: Agree | K13: C; I; A
A14: 6 | B14: 9 | C14: Who Controls Your Robot? An Evaluation of ROS Security Mechanisms | D14: VUL | E14: VUL | F14: Agree | G14: VUL | H14: C; I | I14: C; I | J14: Agree | K14: C; I
A15: 7 | B15: 10 | C15: Robot Operating System 2: The Need for a Holistic Security Approach to Robotic Architectures | D15: VUL | E15: VUL | F15: Agree | G15: VUL | H15: C; I; A | I15: C; I; A | J15: Agree | K15: C; I; A
A16: 8 | B16: 11 | C16: Understanding Misconfigurations in ROS: An Empirical Study and Current Approaches | D16: REL | E16: REL | F16: Agree | G16: REL | H16: CODE; SEM | I16: CODE; SEM | J16: Agree | K16: CODE; SEM
A17: 9 | B17: 12 | C17: The Role of Security in Human-Robot Shared Environments: A Case Study in ROS-based Surveillance Robots | D17: VUL | E17: VUL | F17: Agree | G17: VUL | H17: C; I; A | I17: C; I; A | J17: Agree | K17: C; I; A
A18: 10 | B18: 13 | C18: A Study on ROS Vulnerabilities and Countermeasure | D18: VUL | E18: VUL | F18: Agree | G18: VUL | H18: C | I18: I | J18: Disagree | K18: C; I
A19: 11 | B19: 14 | C19: Smart Malware that Uses Leaked Control Data of Robotic Applications: The Case of Raven-II Surgical Robots | D19: VUL | E19: VUL | F19: Agree | G19: VUL | H19: C; I | I19: C; I | J19: Agree | K19: C; I
A20: 12 | B20: 15 | C20: ROSploit: Cybersecurity Tool for ROS | D20: VUL | E20: VUL | F20: Agree | G20: VUL | H20: C; I | I20: C; I | J20: Agree | K20: C; I
... A99: 91 | B99: 94 | C99: ROSDiscover: Statically Detecting Run-Time Architecture Misconfigurations in Robotics Systems | D99: REL | E99: REL | F99: Agree | G99: REL | H99: SEM | I99: SEM | J99: Agree | K99: SEM

Sheet 06_Kappa_Calculation
A1: Cohen's Kappa Calculation / 卡帕系数计算
A2: Scope: randomly selected validation sample from source rows 60–86 (27 of 91 studies, 29.7%). Major Category and Primary Subcategory only; final adjudicated codes are excluded from reliability estimation.
A4: Verified sample results (source rows 60–86, N=27): Major Category κ = 1.0000 (27/27 agreements); Primary Subcategory κ = 0.8393 (24/27 exact label-set agreements).
A5: Primary Subcategory is treated as one nominal category per canonicalized label set; partial overlap between two sets is recorded as disagreement.
A7: Dimension | B7: Unit of analysis | C7: N | D7: Agreements | E7: Disagreements | F7: Observed agreement Po | G7: Expected agreement Pe | H7: Cohen's κ | I7: Interpretation
A8: Major Category | B8: Single nominal category | C8: =COUNTA('05_Coding_Audit'!$A$65:$A$91) -> 27 | D8: =COUNTIF('05_Coding_Audit'!$F$65:$F$91,"Agree") -> 27 | E8: =C8-D8 -> 0 | F8: =D8/C8 -> 1 | G8: =F19 -> 0.80246914 | H8: =(F8-G8)/(1-G8) -> 1 | I8: =IF(H8>=0.81,"Almost perfect",IF(H8>=0.61,"Substantial",IF(H8>=0.41,"Moderate",IF(H8>=0.21,"Fair",IF(H8>=0.01,"Slight","Poor"))))) -> Almost perfect
A9: Primary Subcategory | B9: Exact canonicalized multi-label set | C9: =COUNTA('05_Coding_Audit'!$A$65:$A$91) -> 27 | D9: =COUNTIF('05_Coding_Audit'!$J$65:$J$91,"Agree") -> 24 | E9: =C9-D9 -> 3 | F9: =D9/C9 -> 0.88888889 | G9: =F37 -> 0.30864198 | H9: =(F9-G9)/(1-G9) -> 0.83928571 | I9: =IF(H9>=0.81,"Almost perfect",IF(H9>=0.61,"Substantial",IF(H9>=0.41,"Moderate",IF(H9>=0.21,"Fair",IF(H9>=0.01,"Slight","Poor"))))) -> Almost perfect
A12: Major Category marginal distributions and expected agreement | H12: Major disagreement profile
A14: Category | B14: Reviewer 1 Count | C14: Reviewer 2 Count | D14: Reviewer 1 Proportion | E14: Reviewer 2 Proportion | F14: Pe Contribution | H14: Measure | I14: Value
A15: VUL | B15: =COUNTIF('05_Coding_Audit'!$D$65:$D$91,A15) -> 3 | C15: =COUNTIF('05_Coding_Audit'!$E$65:$E$91,A15) -> 3 | D15: =B15/$C$8 -> 0.11111111 | E15: =C15/$C$8 -> 0.11111111 | F15: =D15*E15 -> 0.012345679 | H15: VUL↔REL disagreements | I15: =COUNTIFS('05_Coding_Audit'!$D$65:$D$91,"VUL",'05_Coding_Audit'!$E$65:$E$91,"REL")+COUNTIFS('05_Coding_Audit'!$D$65:$D$91,"REL",'05_Coding_Audit'!$E$65:$E$91,"VUL") -> 0
A16: REL | B16: =COUNTIF('05_Coding_Audit'!$D$65:$D$91,A16) -> 24 | C16: =COUNTIF('05_Coding_Audit'!$E$65:$E$91,A16) -> 24 | D16: =B16/$C$8 -> 0.88888889 | E16: =C16/$C$8 -> 0.88888889 | F16: =D16*E16 -> 0.79012346 | H16: Other major disagreements | I16: =E8-I15 -> 0
A17: BOTH | B17: =COUNTIF('05_Coding_Audit'!$D$65:$D$91,A17) -> 0 | C17: =COUNTIF('05_Coding_Audit'!$E$65:$E$91,A17) -> 0 | D17: =B17/$C$8 -> 0 | E17: =C17/$C$8 -> 0 | F17: =D17*E17 -> 0 | H17: Total disagreements | I17: =E8 -> 0
A18: — | B18: =COUNTIF('05_Coding_Audit'!$D$65:$D$91,A18) -> 0 | C18: =COUNTIF('05_Coding_Audit'!$E$65:$E$91,A18) -> 0 | D18: =B18/$C$8 -> 0 | E18: =C18/$C$8 -> 0 | F18: =D18*E18 -> 0 | H18: Final codes excluded from κ | I18: Yes
A19: Expected agreement Pe (Major Category) | F19: =SUM(F15:F18) -> 0.80246914
A21: Primary Subcategory exact-set marginal distributions and expected agreement
A23: Canonicalized label set | B23: Reviewer 1 Count | C23: Reviewer 2 Count | D23: Reviewer 1 Proportion | E23: Reviewer 2 Proportion | F23: Pe Contribution
A24: A | B24: =COUNTIF('05_Coding_Audit'!$H$65:$H$91,A24) -> 0 | C24: =COUNTIF('05_Coding_Audit'!$I$65:$I$91,A24) -> 0 | D24: =B24/$C$9 -> 0 | E24: =C24/$C$9 -> 0 | F24: =D24*E24 -> 0
A25: A; CODE | B25: =COUNTIF('05_Coding_Audit'!$H$65:$H$91,A25) -> 0 | C25: =COUNTIF('05_Coding_Audit'!$I$65:$I$91,A25) -> 0 | D25: =B25/$C$9 -> 0 | E25: =C25/$C$9 -> 0 | F25: =D25*E25 -> 0
A26: C | B26: =COUNTIF('05_Coding_Audit'!$H$65:$H$91,A26) -> 0 | C26: =COUNTIF('05_Coding_Audit'!$I$65:$I$91,A26) -> 1 | D26: =B26/$C$9 -> 0 | E26: =C26/$C$9 -> 0.037037037 | F26: =D26*E26 -> 0
A27: C; A | B27: =COUNTIF('05_Coding_Audit'!$H$65:$H$91,A27) -> 0 | C27: =COUNTIF('05_Coding_Audit'!$I$65:$I$91,A27) -> 0 | D27: =B27/$C$9 -> 0 | E27: =C27/$C$9 -> 0 | F27: =D27*E27 -> 0
A28: C; I | B28: =COUNTIF('05_Coding_Audit'!$H$65:$H$91,A28) -> 0 | C28: =COUNTIF('05_Coding_Audit'!$I$65:$I$91,A28) -> 0 | D28: =B28/$C$9 -> 0 | E28: =C28/$C$9 -> 0 | F28: =D28*E28 -> 0
A29: C; I; A | B29: =COUNTIF('05_Coding_Audit'!$H$65:$H$91,A29) -> 0 | C29: =COUNTIF('05_Coding_Audit'!$I$65:$I$91,A29) -> 0 | D29: =B29/$C$9 -> 0 | E29: =C29/$C$9 -> 0 | F29: =D29*E29 -> 0
A30: CODE | B30: =COUNTIF('05_Coding_Audit'!$H$65:$H$91,A30) -> 10 | C30: =COUNTIF('05_Coding_Audit'!$I$65:$I$91,A30) -> 10 | D30: =B30/$C$9 -> 0.37037037 | E30: =C30/$C$9 -> 0.37037037 | F30: =D30*E30 -> 0.13717421
A31: CODE; SEM | B31: =COUNTIF('05_Coding_Audit'!$H$65:$H$91,A31) -> 3 | C31: =COUNTIF('05_Coding_Audit'!$I$65:$I$91,A31) -> 4 | D31: =B31/$C$9 -> 0.11111111 | E31: =C31/$C$9 -> 0.14814815 | F31: =D31*E31 -> 0.016460905
A32: I | B32: =COUNTIF('05_Coding_Audit'!$H$65:$H$91,A32) -> 2 | C32: =COUNTIF('05_Coding_Audit'!$I$65:$I$91,A32) -> 1 | D32: =B32/$C$9 -> 0.074074074 | E32: =C32/$C$9 -> 0.037037037 | F32: =D32*E32 -> 0.0027434842
A33: I; A | B33: =COUNTIF('05_Coding_Audit'!$H$65:$H$91,A33) -> 1 | C33: =COUNTIF('05_Coding_Audit'!$I$65:$I$91,A33) -> 1 | D33: =B33/$C$9 -> 0.037037037 | E33: =C33/$C$9 -> 0.037037037 | F33: =D33*E33 -> 0.0013717421
A34: I; A; CODE | B34: =COUNTIF('05_Coding_Audit'!$H$65:$H$91,A34) -> 0 | C34: =COUNTIF('05_Coding_Audit'!$I$65:$I$91,A34) -> 0 | D34: =B34/$C$9 -> 0 | E34: =C34/$C$9 -> 0 | F34: =D34*E34 -> 0
A35: SEM | B35: =COUNTIF('05_Coding_Audit'!$H$65:$H$91,A35) -> 11 | C35: =COUNTIF('05_Coding_Audit'!$I$65:$I$91,A35) -> 10 | D35: =B35/$C$9 -> 0.40740741 | E35: =C35/$C$9 -> 0.37037037 | F35: =D35*E35 -> 0.15089163
A36: — | B36: =COUNTIF('05_Coding_Audit'!$H$65:$H$91,A36) -> 0 | C36: =COUNTIF('05_Coding_Audit'!$I$65:$I$91,A36) -> 0 | D36: =B36/$C$9 -> 0 | E36: =C36/$C$9 -> 0 | F36: =D36*E36 -> 0
A37: Expected agreement Pe (Primary Subcategory) | F37: =SUM(F24:F36) -> 0.30864198
A40: Calculation definition and reporting record
A42: Item | C42: Formula | E42: Meaning
A43: Observed agreement | C43: Po = A / N | E43: A is the number of exact agreements and N is the number of independently coded studies.
A44: Expected agreement | C44: Pe = SUM(p1j * p2j) | E44: For every nominal category j, the two reviewers' marginal proportions are multiplied and then summed.
A45: Cohen's kappa | C45: kappa = (Po - Pe) / (1 - Pe) | E45: Chance-corrected agreement between the two independent reviewers.
A46: Adjudication | C46: Not included in kappa | E46: Final codes are retained as the resolved coding record and are not used to inflate the reliability estimate.
A49: Reporting sentence: Two reviewers independently coded a randomly selected validation sample of 27 studies (source rows 60–86). Cohen's kappa was 1.000 for Major Category and 0.839 for Primary Subcategory, indicating almost perfect and almost perfect agreement, respectively, under the exact-set coding rule. All disagreements were resolved by full-text re-examination and consensus.
